<?xml version="1.0"?>
<robot xmlns:xacro="http://ros.org/wiki/xacro">

    <xacro:include filename="$(find earth_gz_classic)/urdf/params.xacro"/>

    <xacro:macro name="dynamics" params="dyn_damping dyn_friction">
            <!-- <dynamics damping="${dyn_damping}" friction="${dyn_friction}"/> -->
    </xacro:macro>

    <joint name="${left_spin_to_skid_joint_name}" type="fixed">
        <origin xyz="0 0 -0.3" rpy="0 0 0"/>
        <parent link="${left_spinning_wheel_link_name}"/>
        <child link="${left_skid_wheel_spinning_link_name}"/>
        <axis xyz="0 0 1"/>
        <!-- <xacro:dynamics dyn_damping="0.1" dyn_friction="0.2"/> -->
    </joint>

    <joint name="${left_free_to_skid_joint_name}" type="fixed">
        <origin xyz="0 0 0.3" rpy="0 0 0"/>
        <parent link="${left_front_wheel_link_name}"/>
        <child link="${left_skid_wheel_free_link_name}"/>
        <axis xyz="0 0 1"/>
        <!-- <xacro:dynamics dyn_damping="0.1" dyn_friction="0.2"/> -->
    </joint>


    <joint name="${right_spin_to_skid_joint_name}" type="fixed">
        <origin xyz="0 0 -0.3" rpy="0 0 0"/>
        <parent link="${right_spinning_wheel_link_name}"/>
        <child link="${right_skid_wheel_spinning_link_name}"/>
        <axis xyz="0 0 1"/>
        <!-- <xacro:dynamics dyn_damping="0.1" dyn_friction="0.2"/> -->
    </joint>

    <joint name="${right_free_to_skid_joint_name}" type="fixed">
        <origin xyz="0 0 -0.3" rpy="0 0 0"/>
        <parent link="${right_front_wheel_link_name}"/>
        <child link="${right_skid_wheel_free_link_name}"/>
        <axis xyz="0 0 1"/>
        <!-- <xacro:dynamics dyn_damping="0.1" dyn_friction="0.2"/> -->
    </joint>


    <joint name="${base_to_turret_joint_name}" type="fixed">
        <origin xyz="0 0 0.55" rpy="0 0 0" />
        <parent link="${base_link_name}" />
        <child link="${turret_link_name}" />
        <axis xyz="0 0 1"/>
    </joint>

    <joint name="${left_spinning_to_turret_joint_name}" type="continuous">
        <origin xyz="-0.5739999999999999547 -0.80000000000000015543 -0.2750000000000000222" rpy="1.570796326794896558 -0.3547477759675310427 1.5707963267948976682" />
        <parent link="${turret_link_name}" />
        <child link="${left_spinning_wheel_link_name}" />
        <axis xyz="0 0 1"/>
        <limit effort="1000" velocity="1" />
        <!-- <xacro:dynamics dyn_damping="0.1" dyn_friction="0.2"/> -->
    </joint>

    <joint name="${right_spinning_to_turret_joint_name}" type="continuous">
        <origin xyz="0.5739999999999999547 -0.80000000000000004441 -0.2750000000000000222" rpy="1.570796326794896558 -1.2984776443375001254 -1.5707963267948972241" />
        <parent link="${turret_link_name}" />
        <child link="${right_spinning_wheel_link_name}" />
        <axis xyz="0 0 1"/>
        <limit effort="1000" velocity="1" />
        <!-- <xacro:dynamics dyn_damping="0.1" dyn_friction="0.2"/> -->
    </joint>

    <joint name="${left_front_to_turret_joint_name}" type="continuous">
        <origin xyz="-0.61299999999999998934 0.80000000000000026645 -0.2750000000000000222" rpy="1.570796326794896558 -1.0222876983448163646 -1.5707963267948941155" />
        <parent link="${turret_link_name}" />
        <child link="${left_front_wheel_link_name}" />
        <axis xyz="0 0 1"/>
        <limit effort="1000" velocity="1" />
        <!-- <xacro:dynamics dyn_damping="0.1" dyn_friction="0.2"/> -->
    </joint>

    <joint name="${right_front_to_turret_joint_name}" type="continuous">
        <origin xyz="0.54800000000000004263 0.80000000000000015543 -0.27499999999999996669" rpy="1.57079632679489678 -1.1102232252180887662e-16 -1.5707963267948976682" />
        <parent link="${turret_link_name}" />
        <child link="${right_front_wheel_link_name}" />
        <axis xyz="0 0 1"/>
        <limit effort="1000" velocity="1" />
        <!-- <xacro:dynamics dyn_damping="0.1" dyn_friction="0.2"/> -->
    </joint>

    <joint name="${plow_to_base_joint_name}" type="revolute">
        <origin xyz="-0.25500000000000005995 0.4880000000000002669 -0.20500000000000001554" rpy="1.570796326794896558 -1.3195606112546109934 -1.57079632679489678" />
        <parent link="${turret_link_name}" />
        <child link="${plow_link_name}" />
        <axis xyz="0 0 1"/>
        <limit effort="1000" velocity="1" lower="0.2" upper="0" />
        <!-- <xacro:dynamics dyn_damping="0.1" dyn_friction="0.2"/> -->
    </joint>

    <joint name="${excavator_slew_joint_name}" type="continuous">
        <origin xyz="0 0 0.1" rpy="-5.5511151231419568159e-17 -1.1102230246202266528e-16 -3.1415" />
        <parent link="${turret_link_name}" />
        <child link="${cabin_link_name}" />
        <axis xyz="0 0 1"/>
        <limit effort="1000" velocity="1"/>
        <!-- <xacro:dynamics dyn_damping="0.1" dyn_friction="0.2"/> -->
    </joint>


    <joint name="${arm_to_bucket_joint_name}" type="revolute">
        <origin xyz="0.12000000000000410338 -1.5403327562575612752 9.4368957093138305936e-16" rpy="3.1415926535897917837 1.8859935444767496044e-16 -1.5963552846072552871" />
        <parent link="${arm_link_name}" />
        <child link="bucket_base" />
        <axis xyz="0 0 1"/>
        <limit effort="1000" velocity="1" lower="-1.2217304763960306069" upper="0.87266462599716476678"/>
        <!-- <xacro:dynamics dyn_damping="0.1" dyn_friction="0.2"/> -->
    </joint>

    <joint name="${boom_to_arm_joint_name}" type="revolute">
        <origin xyz="-0.84000000000000030198 2.3549999999999999822 -0.13500000000000003664" rpy="3.1415926535897922278 6.9325343981756730312e-15 2.5555644018935783635" />
        <parent link="${boom_link_name}" />
        <child link="${arm_link_name}" />
        <axis xyz="0 0 1"/>
        <limit effort="1000" velocity="1" lower="-0.5" upper="1.57"/>
        <!-- <xacro:dynamics dyn_damping="0.1" dyn_friction="0.2"/> -->
    </joint>


    <joint name="${swing_to_boom_joint_name}" type="revolute">
        <origin xyz="0.079999999999996157518 0.074999999999997291056 -0.1500000000000039635" rpy="-1.570796326794896558 0.39285813115170314935 -1.5707963267949009989" />
        <parent link="${swing_link_name}" />
        <child link="${boom_link_name}" />
        <axis xyz="0 0 1"/>
        <limit effort="1000" velocity="1.0" lower="-0.4" upper="1" />
        <!-- <xacro:dynamics dyn_damping="0.1" dyn_friction="0.2"/> -->
    </joint>

    <joint name="${cabin_to_swing_joint_name}" type="revolute">
        <origin xyz="-0.040707723917193447405 -0.80673603465099630316 0.38039999999999996039" rpy="3.141592653589793116 4.8797124238540929311e-17 0" />
        <parent link="${cabin_link_name}" />
        <child link="${swing_link_name}" />
        <axis xyz="0 0 1"/>
        <limit effort="1000" velocity="1" lower="-0.1" upper="0.1" />
        <!-- <xacro:dynamics dyn_damping="0.1" dyn_friction="0.2"/> -->
    </joint>
</robot>
