<?xml version="1.0" ?>
<!-- =================================================================================== -->
<!-- |    This document was autogenerated by xacro from robot.xacro                    | -->
<!-- |    EDITING THIS FILE BY HAND IS NOT RECOMMENDED                                 | -->
<!-- =================================================================================== -->
<robot name="excavator">
  <joint name="left_spin_to_skid" type="fixed">
    <origin rpy="0 0 0" xyz="0 0 -0.3"/>
    <parent link="left_spinning_wheel_link"/>
    <child link="left_skid_wheel_spinning"/>
    <axis xyz="0 0 1"/>
    <dynamics damping="10000" friction="0.2"/>
  </joint>
  <joint name="left_free_to_skid" type="fixed">
    <origin rpy="0 0 0" xyz="0 0 0.3"/>
    <parent link="left_front_wheel_link"/>
    <child link="left_skid_wheel_free"/>
    <axis xyz="0 0 1"/>
    <dynamics damping="10000" friction="0.2"/>
  </joint>
  <joint name="right_spin_to_skid" type="fixed">
    <origin rpy="0 0 0" xyz="0 0 -0.3"/>
    <parent link="right_spinning_wheel_link"/>
    <child link="right_skid_wheel_spinning"/>
    <axis xyz="0 0 1"/>
    <dynamics damping="10000" friction="0.2"/>
  </joint>
  <joint name="right_free_to_skid" type="fixed">
    <origin rpy="0 0 0" xyz="0 0 -0.3"/>
    <parent link="right_front_wheel_link"/>
    <child link="right_skid_wheel_free"/>
    <axis xyz="0 0 1"/>
    <dynamics damping="10000" friction="0.2"/>
  </joint>
  <joint name="base_to_turret" type="fixed">
    <origin rpy="0 0 0" xyz="0 0 0.55"/>
    <parent link="base_link"/>
    <child link="turret_base"/>
    <axis xyz="0 0 1"/>
  </joint>
  <joint name="left_spinning_to_turret" type="continuous">
    <origin rpy="1.570796326794896558 -0.3547477759675310427 1.5707963267948976682" xyz="-0.5739999999999999547 -0.80000000000000015543 -0.2750000000000000222"/>
    <parent link="turret_base"/>
    <child link="left_spinning_wheel_link"/>
    <axis xyz="0 0 1"/>
    <limit effort="100000" velocity="1"/>
    <dynamics damping="10000" friction="0.2"/>
  </joint>
  <joint name="right_spinning_to_turret" type="continuous">
    <origin rpy="1.570796326794896558 -1.2984776443375001254 -1.5707963267948972241" xyz="0.5739999999999999547 -0.80000000000000004441 -0.2750000000000000222"/>
    <parent link="turret_base"/>
    <child link="right_spinning_wheel_link"/>
    <axis xyz="0 0 1"/>
    <limit effort="10000" velocity="1"/>
    <dynamics damping="10000" friction="0.2"/>
  </joint>
  <joint name="left_front_to_turret" type="continuous">
    <origin rpy="1.570796326794896558 -1.0222876983448163646 -1.5707963267948941155" xyz="-0.61299999999999998934 0.80000000000000026645 -0.2750000000000000222"/>
    <parent link="turret_base"/>
    <child link="left_front_wheel_link"/>
    <axis xyz="0 0 1"/>
    <limit effort="100000" velocity="1"/>
    <dynamics damping="10000" friction="0.2"/>
  </joint>
  <joint name="right_front_to_turret" type="continuous">
    <origin rpy="1.57079632679489678 -1.1102232252180887662e-16 -1.5707963267948976682" xyz="0.54800000000000004263 0.80000000000000015543 -0.27499999999999996669"/>
    <parent link="turret_base"/>
    <child link="right_front_wheel_link"/>
    <axis xyz="0 0 1"/>
    <limit effort="100000" velocity="1"/>
    <dynamics damping="10000" friction="0.2"/>
  </joint>
  <joint name="plow_to_base" type="revolute">
    <origin rpy="1.570796326794896558 -1.3195606112546109934 -1.57079632679489678" xyz="-0.25500000000000005995 0.4880000000000002669 -0.20500000000000001554"/>
    <parent link="turret_base"/>
    <child link="push_blade_base"/>
    <axis xyz="0 0 1"/>
    <limit effort="100000" lower="0.2" upper="0" velocity="1"/>
    <dynamics damping="10000" friction="0.2"/>
  </joint>
  <joint name="excavator_slew" type="continuous">
    <origin rpy="-5.5511151231419568159e-17 -1.1102230246202266528e-16 -3.1415" xyz="0 0 0.1"/>
    <parent link="turret_base"/>
    <child link="cabin_base"/>
    <axis xyz="0 0 1"/>
    <limit effort="100000" velocity="1"/>
    <dynamics damping="10000" friction="0.2"/>
  </joint>
  <joint name="arm_to_bucket" type="revolute">
    <origin rpy="3.1415926535897917837 1.8859935444767496044e-16 -1.5963552846072552871" xyz="0.12000000000000410338 -1.5403327562575612752 9.4368957093138305936e-16"/>
    <parent link="arm_base"/>
    <child link="bucket_base"/>
    <axis xyz="0 0 1"/>
    <limit effort="100000" lower="-1.2217304763960306069" upper="0.87266462599716476678" velocity="1"/>
    <dynamics damping="10000" friction="0.2"/>
  </joint>
  <joint name="boom_to_arm" type="revolute">
    <origin rpy="3.1415926535897922278 6.9325343981756730312e-15 2.5555644018935783635" xyz="-0.84000000000000030198 2.3549999999999999822 -0.13500000000000003664"/>
    <parent link="boom_base"/>
    <child link="arm_base"/>
    <axis xyz="0 0 1"/>
    <limit effort="100000" lower="-0.5" upper="1.57" velocity="1"/>
    <dynamics damping="10000" friction="0.2"/>
  </joint>
  <joint name="swing_to_boom" type="revolute">
    <origin rpy="-1.570796326794896558 0.39285813115170314935 -1.5707963267949009989" xyz="0.079999999999996157518 0.074999999999997291056 -0.1500000000000039635"/>
    <parent link="swing_base"/>
    <child link="boom_base"/>
    <axis xyz="0 0 1"/>
    <limit effort="100000" lower="-0.4" upper="1" velocity="1.0"/>
    <dynamics damping="10000" friction="0.2"/>
  </joint>
  <joint name="cabin_to_swing" type="revolute">
    <origin rpy="3.141592653589793116 4.8797124238540929311e-17 0" xyz="-0.040707723917193447405 -0.80673603465099630316 0.38039999999999996039"/>
    <parent link="cabin_base"/>
    <child link="swing_base"/>
    <axis xyz="0 0 1"/>
    <limit effort="100000" lower="-0.1" upper="0.1" velocity="1"/>
    <dynamics damping="10000" friction="0.2"/>
  </joint>
  <!-- <xacro:gazebo_joint_dynamics joint_name="${excavator_slew_joint_name}" stiffness="100" damping="5"/>
    <xacro:gazebo_joint_dynamics joint_name="${plow_to_base_joint_name}" stiffness="100" damping="5"/>
    <xacro:gazebo_joint_dynamics joint_name="${arm_to_bucket_joint_name}" stiffness="100" damping="5"/>
    <xacro:gazebo_joint_dynamics joint_name="${boom_to_arm_joint_name}" stiffness="100" damping="5"/>
    <xacro:gazebo_joint_dynamics joint_name="${swing_to_boom_joint_name}" stiffness="100" damping="5"/>
    <xacro:gazebo_joint_dynamics joint_name="${cabin_to_swing_joint_name}" stiffness="100" damping="5"/>
    <xacro:gazebo_joint_dynamics joint_name="${left_spin_to_skid_joint_name}" stiffness="100" damping="5"/>
    <xacro:gazebo_joint_dynamics joint_name="${left_free_to_skid_joint_name}" stiffness="100" damping="5"/>
    <xacro:gazebo_joint_dynamics joint_name="${right_spin_to_skid_joint_name}" stiffness="100" damping="5"/>
    <xacro:gazebo_joint_dynamics joint_name="${right_free_to_skid_joint_name}" stiffness="100" damping="5"/> -->
  <transmission name="plow_to_base_trans">
    <type>transmission_interface/SimpleTransmission</type>
    <joint name="plow_to_base">
      <hardwareInterface>hardware_interface/VelocityJointInterface</hardwareInterface>
    </joint>
    <actuator name="plow_to_base_motor">
      <hardwareInterface>hardware_interface/VelocityJointInterface</hardwareInterface>
      <mechanicalReduction>1</mechanicalReduction>
    </actuator>
  </transmission>
  <transmission name="excavator_slew_trans">
    <type>transmission_interface/SimpleTransmission</type>
    <joint name="excavator_slew">
      <hardwareInterface>hardware_interface/VelocityJointInterface</hardwareInterface>
    </joint>
    <actuator name="excavator_slew_motor">
      <hardwareInterface>hardware_interface/VelocityJointInterface</hardwareInterface>
      <mechanicalReduction>1</mechanicalReduction>
    </actuator>
  </transmission>
  <transmission name="cabin_to_swing_trans">
    <type>transmission_interface/SimpleTransmission</type>
    <joint name="cabin_to_swing">
      <hardwareInterface>hardware_interface/VelocityJointInterface</hardwareInterface>
    </joint>
    <actuator name="cabin_to_swing_motor">
      <hardwareInterface>hardware_interface/VelocityJointInterface</hardwareInterface>
      <mechanicalReduction>1</mechanicalReduction>
    </actuator>
  </transmission>
  <transmission name="swing_to_boom_trans">
    <type>transmission_interface/SimpleTransmission</type>
    <joint name="swing_to_boom">
      <hardwareInterface>hardware_interface/VelocityJointInterface</hardwareInterface>
    </joint>
    <actuator name="swing_to_boom_motor">
      <hardwareInterface>hardware_interface/VelocityJointInterface</hardwareInterface>
      <mechanicalReduction>1</mechanicalReduction>
    </actuator>
  </transmission>
  <transmission name="boom_to_arm_trans">
    <type>transmission_interface/SimpleTransmission</type>
    <joint name="boom_to_arm">
      <hardwareInterface>hardware_interface/VelocityJointInterface</hardwareInterface>
    </joint>
    <actuator name="boom_to_arm_motor">
      <hardwareInterface>hardware_interface/VelocityJointInterface</hardwareInterface>
      <mechanicalReduction>1</mechanicalReduction>
    </actuator>
  </transmission>
  <transmission name="arm_to_bucket_trans">
    <type>transmission_interface/SimpleTransmission</type>
    <joint name="arm_to_bucket">
      <hardwareInterface>hardware_interface/VelocityJointInterface</hardwareInterface>
    </joint>
    <actuator name="arm_to_bucket_motor">
      <hardwareInterface>hardware_interface/VelocityJointInterface</hardwareInterface>
      <mechanicalReduction>1</mechanicalReduction>
    </actuator>
  </transmission>
  <link name="base_link"/>
  <link name="cabin_base">
    <visual>
      <origin rpy="0 0 0" xyz="0.1592 -0.2513 0.2814"/>
      <geometry>
        <mesh filename="file:///home/moog-2/nav2_ws/install/earth_gz_ign/share/earth_gz_ign/meshes/compact_excavator_cabin_body.stl"/>
      </geometry>
      <material name="compact_excavator_cabin_body_material">
        <color rgba="0.2314 0.3804 0.7059 1.0"/>
      </material>
    </visual>
    <collision>
      <origin rpy="0 0 0" xyz="0.1592 -0.2513 0.2814"/>
      <geometry>
        <mesh filename="file:///home/moog-2/nav2_ws/install/earth_gz_ign/share/earth_gz_ign/meshes/compact_excavator_cabin_body.stl"/>
      </geometry>
    </collision>
    <inertial>
      <origin rpy="0 0 0" xyz="-0.1469 0.4412 0.4509"/>
      <mass value="9732.8039"/>
      <inertia ixx="3175.1655302028038932" ixy="-269.97312494382822479" ixz="167.61780128589879268" iyy="2627.6328649732372469" iyz="-193.85494965010886403" izz="3742.616047274826542"/>
    </inertial>
  </link>
  <link name="turret_base">
    <visual>
      <origin rpy="0 0 0" xyz="0 0 0"/>
      <geometry>
        <mesh filename="file:///home/moog-2/nav2_ws/install/earth_gz_ign/share/earth_gz_ign/meshes/compact_excavator_frame_body.stl"/>
      </geometry>
      <material name="compact_excavator_frame_body_material">
        <color rgba="0.9176 0.9176 0.9176 1.0"/>
      </material>
    </visual>
    <collision>
      <origin rpy="0 0 0" xyz="0 0 0"/>
      <geometry>
        <mesh filename="file:///home/moog-2/nav2_ws/install/earth_gz_ign/share/earth_gz_ign/meshes/compact_excavator_frame_body.stl"/>
      </geometry>
    </collision>
    <inertial>
      <origin rpy="0 0 0" xyz="-0.0068 -0.1255 -0.1865"/>
      <mass value="459.1171"/>
      <inertia ixx="103.54309263053609413" ixy="2.8689912175751035583" ixz="-0.26918599165092144121" iyy="71.550382439979060223" iyz="-8.7881744003938315757" izz="164.71779214088334697"/>
    </inertial>
  </link>
  <link name="left_spinning_wheel_link">
    <visual>
      <origin rpy="-4.71 0 0" xyz="0 -2.0816681711721685133e-17 -0.015000000000000124345"/>
      <geometry>
        <mesh filename="file:///home/moog-2/nav2_ws/install/earth_gz_ign/share/earth_gz_ign/meshes/compact_excavator_main_drive_wheel.stl"/>
      </geometry>
      <material name="compact_excavator_main_drive_wheel_material">
        <color rgba="0.91764705882352937127 0.91764705882352937127 0.91764705882352937127 1.0"/>
      </material>
    </visual>
    <collision>
      <origin rpy="-4.71 0 0" xyz="0 -2.0816681711721685133e-17 -0.015000000000000124345"/>
      <geometry>
        <mesh filename="file:///home/moog-2/nav2_ws/install/earth_gz_ign/share/earth_gz_ign/meshes/compact_excavator_main_drive_wheel.stl"/>
      </geometry>
    </collision>
    <inertial>
      <origin rpy="0 0 0" xyz="2.7929494467705319618e-05 -2.4226277708340838271e-16 -0.047030821852304713349"/>
      <mass value="35.98629134579582"/>
      <inertia ixx="0.20071737580058110484" ixy="2.1151248144254331483e-17" ixz="7.9696042408110000254e-05" iyy="0.20066206838835709547" iyz="2.9623558171777900037e-16" izz="0.29333573070696433716"/>
    </inertial>
  </link>
  <link name="right_spinning_wheel_link">
    <visual>
      <origin rpy="1.57 0 0" xyz="-6.9388939039072283776e-18 0 -0.015000000000000013323"/>
      <geometry>
        <mesh filename="file:///home/moog-2/nav2_ws/install/earth_gz_ign/share/earth_gz_ign/meshes/compact_excavator_main_drive_wheel.stl"/>
      </geometry>
      <material name="compact_excavator_main_drive_wheel_material">
        <color rgba="0.91764705882352937127 0.91764705882352937127 0.91764705882352937127 1.0"/>
      </material>
    </visual>
    <collision>
      <origin rpy="1.57 0 0" xyz="-6.9388939039072283776e-18 0 -0.015000000000000013323"/>
      <geometry>
        <mesh filename="file:///home/moog-2/nav2_ws/install/earth_gz_ign/share/earth_gz_ign/meshes/compact_excavator_main_drive_wheel.stl"/>
      </geometry>
    </collision>
    <inertial>
      <origin rpy="0 0 0" xyz="2.7929494467698390888e-05 -2.2144767850277592569e-16 -0.047030821852304602326"/>
      <mass value="35.98629134579582"/>
      <inertia ixx="0.20071737580058127137" ixy="6.1250580134766935832e-18" ixz="7.9696042408110027359e-05" iyy="0.20066206838835703996" iyz="2.9623106429686494369e-16" izz="0.29333573070696433716"/>
    </inertial>
  </link>
  <link name="left_front_wheel_link">
    <visual>
      <origin rpy="0 1.570796326794896336 0" xyz="1.1102230246251565404e-16 -1.1102230246251565404e-16 -0.032500000000000084377"/>
      <geometry>
        <mesh filename="file:///home/moog-2/nav2_ws/install/earth_gz_ign/share/earth_gz_ign/meshes/compact_excavator_front_wheel.stl"/>
      </geometry>
      <material name="compact_excavator_front_wheel_material">
        <color rgba="0.91764705882352937127 0.91764705882352937127 0.91764705882352937127 1.0"/>
      </material>
    </visual>
    <collision>
      <origin rpy="0 1.570796326794896336 0" xyz="1.1102230246251565404e-16 -1.1102230246251565404e-16 -0.032500000000000084377"/>
      <geometry>
        <mesh filename="file:///home/moog-2/nav2_ws/install/earth_gz_ign/share/earth_gz_ign/meshes/compact_excavator_front_wheel.stl"/>
      </geometry>
    </collision>
    <inertial>
      <origin rpy="0 0 0" xyz="8.8979772495497043726e-17 -1.1262368284473494847e-16 -0.032500000000000070499"/>
      <mass value="17.646735913929575"/>
      <inertia ixx="0.153078316536178205" ixy="1.0629206596102168903e-17" ixz="2.6922495826861160064e-17" iyy="0.15307831653617814949" iyz="6.9747558075870228735e-33" izz="0.29963755764746907717"/>
    </inertial>
  </link>
  <link name="right_front_wheel_link">
    <visual>
      <origin rpy="-3.14 -1.570796326794896336 0" xyz="-2.7755575615628913511e-17 0 -0.032500000000000084377"/>
      <geometry>
        <mesh filename="file:///home/moog-2/nav2_ws/install/earth_gz_ign/share/earth_gz_ign/meshes/compact_excavator_front_wheel.stl"/>
      </geometry>
      <material name="compact_excavator_front_wheel_material">
        <color rgba="0.91764705882352937127 0.91764705882352937127 0.91764705882352937127 1.0"/>
      </material>
    </visual>
    <collision>
      <origin rpy="-3.14 -1.570796326794896336 0" xyz="-2.7755575615628913511e-17 0 -0.032500000000000084377"/>
      <geometry>
        <mesh filename="file:///home/moog-2/nav2_ws/install/earth_gz_ign/share/earth_gz_ign/meshes/compact_excavator_front_wheel.stl"/>
      </geometry>
    </collision>
    <inertial>
      <origin rpy="0 0 0" xyz="-2.7755575615628913511e-17 0 -0.032500000000000084377"/>
      <mass value="17.646735913929575"/>
      <inertia ixx="0.153078316536178205" ixy="-1.0629206596102168903e-17" ixz="2.6922495826861160064e-17" iyy="0.15307831653617814949" iyz="6.9747558075870228735e-33" izz="0.29963755764746907717"/>
    </inertial>
  </link>
  <link name="push_blade_base">
    <visual>
      <origin rpy="-3.14 -1.57 0" xyz="-0.021564399534920564161 1.0799900599760599018 -0.25500000000000000444"/>
      <geometry>
        <mesh filename="file:///home/moog-2/nav2_ws/install/earth_gz_ign/share/earth_gz_ign/meshes/push_blade_bucket.stl"/>
      </geometry>
      <material name="push_blade_base_material">
        <color rgba="0.61568627450980395466 0.81176470588235294379 0.92941176470588238168 1.0"/>
      </material>
    </visual>
    <collision>
      <origin rpy="-3.14 -1.57 0" xyz="-0.021564399534920564161 1.0799900599760599018 -0.25500000000000000444"/>
      <geometry>
        <mesh filename="file:///home/moog-2/nav2_ws/install/earth_gz_ign/share/earth_gz_ign/meshes/push_blade_bucket.stl"/>
      </geometry>
    </collision>
    <inertial>
      <origin rpy="0 0 0" xyz="-0.10970493109347190241 0.88075063461342828486 -0.25500033703320834633"/>
      <mass value="147.01808168083426"/>
      <inertia ixx="31.881096131626421197" ixy="0.91247385061899932701" ixz="-1.6212090668492922982e-05" iyy="21.196220352263214437" iyz="4.9900082202379639952e-06" izz="13.169227707961496776"/>
    </inertial>
  </link>
  <link name="swing_base">
    <visual>
      <origin rpy="-3.14 -6.1629758220391547298e-33 -3.9110122218931175387e-17" xyz="2.7755575615628913511e-17 0.074999999999999955591 -0.14999999999999996669"/>
      <geometry>
        <mesh filename="file:///home/moog-2/nav2_ws/install/earth_gz_ign/share/earth_gz_ign/meshes/part01_pin_1.stl"/>
      </geometry>
      <material name="part01_pin_1_material">
        <color rgba="0.61568627450980395466 0.81176470588235294379 0.92941176470588238168 1.0"/>
      </material>
    </visual>
    <collision>
      <origin rpy="-3.14 -6.1629758220391547298e-33 -3.9110122218931175387e-17" xyz="2.7755575615628913511e-17 0.074999999999999955591 -0.14999999999999996669"/>
      <geometry>
        <mesh filename="file:///home/moog-2/nav2_ws/install/earth_gz_ign/share/earth_gz_ign/meshes/part01_pin_1.stl"/>
      </geometry>
    </collision>
    <inertial>
      <origin rpy="0 0 0" xyz="-0.026030309007671018073 0.10672288733099301317 0.097553850513847364945"/>
      <mass value="98.14019006227906"/>
      <inertia ixx="2.6085778666185075458" ixy="0.040227300901953748358" ixz="0.42136783119553594679" iyy="3.1665232143977135593" iyz="-0.15916376835413623136" izz="1.7889951810686841593"/>
    </inertial>
  </link>
  <link name="boom_base">
    <visual>
      <origin rpy="-1.57 0 0" xyz="0 -1.1102230246251565404e-16 -0.079999999999999987788"/>
      <geometry>
        <mesh filename="file:///home/moog-2/nav2_ws/install/earth_gz_ign/share/earth_gz_ign/meshes/part02.stl"/>
      </geometry>
      <material name="part02_material">
        <color rgba="0.77647058823529413463 0.7568627450980391913 0.73725490196078435901 1.0"/>
      </material>
    </visual>
    <collision>
      <origin rpy="-1.57 0 0" xyz="0 -1.1102230246251565404e-16 -0.079999999999999987788"/>
      <geometry>
        <mesh filename="file:///home/moog-2/nav2_ws/install/earth_gz_ign/share/earth_gz_ign/meshes/part02.stl"/>
      </geometry>
    </collision>
    <inertial>
      <origin rpy="0 0 0" xyz="-0.04007940207094668611 1.215334476695421273 -0.079873417172118876817"/>
      <mass value="694.1779351385806"/>
      <inertia ixx="242.81245205849677404" ixy="71.370938403077758494" ixz="0.0065905643878567711502" iyy="49.641340591529456105" iyz="-0.034260052091464154866" izz="289.83702909122945357"/>
    </inertial>
  </link>
  <link name="arm_base">
    <visual>
      <origin rpy="1.57 0 0" xyz="0 -2.2204460492503130808e-16 -0.054999999999999882316"/>
      <geometry>
        <mesh filename="file:///home/moog-2/nav2_ws/install/earth_gz_ign/share/earth_gz_ign/meshes/part03.stl"/>
      </geometry>
      <material name="part03_material">
        <color rgba="0.98039215686274505668 0.71372549019607844922 0.0039215686274509803377 1.0"/>
      </material>
    </visual>
    <collision>
      <origin rpy="1.57 0 0" xyz="0 -2.2204460492503130808e-16 -0.054999999999999882316"/>
      <geometry>
        <mesh filename="file:///home/moog-2/nav2_ws/install/earth_gz_ign/share/earth_gz_ign/meshes/part03.stl"/>
      </geometry>
    </collision>
    <inertial>
      <origin rpy="0 0 0" xyz="0.10866226733951289685 -0.60164797350906107365 -0.055167291851018741833"/>
      <mass value="265.34907807560876"/>
      <inertia ixx="57.599134249663784146" ixy="0.078442580554215754485" ixz="0.0049826290162324230956" iyy="1.8968981412117758012" iyz="0.02459901605653430981" izz="58.868680211308259231"/>
    </inertial>
  </link>
  <link name="bucket_base">
    <visual>
      <origin rpy="-3.14 -1.57 0" xyz="0.060000000000000053291 0.14000000000000012434 0.054999999999999993339"/>
      <geometry>
        <mesh filename="file:///home/moog-2/nav2_ws/install/earth_gz_ign/share/earth_gz_ign/meshes/part04.stl"/>
      </geometry>
      <material name="part04_material">
        <color rgba="0.76862745098039220171 0.88627450980392152857 0.95294117647058818044 1.0"/>
      </material>
    </visual>
    <collision>
      <origin rpy="-3.14 -1.57 0" xyz="0.060000000000000053291 0.14000000000000012434 0.054999999999999993339"/>
      <geometry>
        <mesh filename="file:///home/moog-2/nav2_ws/install/earth_gz_ign/share/earth_gz_ign/meshes/part04.stl"/>
      </geometry>
    </collision>
    <inertial>
      <origin rpy="0 0 0" xyz="0.21363777998579594475 0.42618058483691984017 0.055071497454761988988"/>
      <mass value="132.7076593386382"/>
      <inertia ixx="14.03567187790122972" ixy="-1.6652440163767181502" ixz="0.0020270508814650067472" iyy="6.8549730106956987541" iyz="0.0040437120644442776929" izz="11.610921270718170817"/>
    </inertial>
    <visual>
      <origin rpy="-1.57 0 3" xyz="0.078718096856630614955 0.97961106773940276327 0.054999999999992416067"/>
      <geometry>
        <mesh filename="file:///home/moog-2/nav2_ws/install/earth_gz_ign/share/earth_gz_ign/meshes/bucket.stl"/>
      </geometry>
      <material name="bucket_material">
        <color rgba="0.61568627450980395466 0.81176470588235294379 0.92941176470588238168 1.0"/>
      </material>
    </visual>
    <collision>
      <origin rpy="-1.57 0 3" xyz="0.078718096856630614955 0.97961106773940276327 0.054999999999992416067"/>
      <geometry>
        <mesh filename="file:///home/moog-2/nav2_ws/install/earth_gz_ign/share/earth_gz_ign/meshes/bucket.stl"/>
      </geometry>
    </collision>
    <visual>
      <origin rpy="-4.71 -1.57 0" xyz="0.16999999999999237943 0.30800000000000604672 0.054999999999999299449"/>
      <geometry>
        <mesh filename="file:///home/moog-2/nav2_ws/install/earth_gz_ign/share/earth_gz_ign/meshes/bucket_mount.stl"/>
      </geometry>
      <material name="bucket_mount_material">
        <color rgba="0.49803921568627451677 0.49803921568627451677 0.49803921568627451677 1.0"/>
      </material>
    </visual>
    <collision>
      <origin rpy="-4.71 -1.57 0" xyz="0.16999999999999237943 0.30800000000000604672 0.054999999999999299449"/>
      <geometry>
        <mesh filename="file:///home/moog-2/nav2_ws/install/earth_gz_ign/share/earth_gz_ign/meshes/bucket_mount.stl"/>
      </geometry>
    </collision>
  </link>
  <link name="left_skid_wheel_spinning">
    <visual>
      <origin rpy="0 0 0" xyz="0 0 0"/>
      <geometry>
        <cylinder length="0.2" radius="0.25"/>
      </geometry>
      <material name="wheel_material">
        <color rgba="0.5 0.5 0.5 1.0"/>
      </material>
    </visual>
    <collision>
      <origin rpy="0 0 0" xyz="0 0 0"/>
      <geometry>
        <cylinder length="0.2" radius="0.25"/>
      </geometry>
    </collision>
    <surface>
      <friction>
        <ode>
          <mu>1</mu>
          <mu2>1</mu2>
        </ode>
      </friction>
    </surface>
    <inertial>
      <origin rpy="0 0 0" xyz="0 0 0"/>
      <mass value="4319.562500000001"/>
      <inertia ixx="81.89170572916669" ixy="0" ixz="0" iyy="81.89170572916669" iyz="0" izz="134.98632812500003"/>
    </inertial>
  </link>
  <link name="left_skid_wheel_free">
    <visual>
      <origin rpy="0 0 0" xyz="0 0 0"/>
      <geometry>
        <cylinder length="0.2" radius="0.25"/>
      </geometry>
      <material name="wheel_material">
        <color rgba="0.5 0.5 0.5 1.0"/>
      </material>
    </visual>
    <collision>
      <origin rpy="0 0 0" xyz="0 0 0"/>
      <geometry>
        <cylinder length="0.2" radius="0.25"/>
      </geometry>
    </collision>
    <surface>
      <friction>
        <ode>
          <mu>1</mu>
          <mu2>1</mu2>
        </ode>
      </friction>
    </surface>
    <inertial>
      <origin rpy="0 0 0" xyz="0 0 0"/>
      <mass value="4319.562500000001"/>
      <inertia ixx="81.89170572916669" ixy="0" ixz="0" iyy="81.89170572916669" iyz="0" izz="134.98632812500003"/>
    </inertial>
  </link>
  <link name="right_skid_wheel_spinning">
    <visual>
      <origin rpy="0 0 0" xyz="0 0 0"/>
      <geometry>
        <cylinder length="0.2" radius="0.25"/>
      </geometry>
      <material name="wheel_material">
        <color rgba="0.5 0.5 0.5 1.0"/>
      </material>
    </visual>
    <collision>
      <origin rpy="0 0 0" xyz="0 0 0"/>
      <geometry>
        <cylinder length="0.2" radius="0.25"/>
      </geometry>
    </collision>
    <surface>
      <friction>
        <ode>
          <mu>1</mu>
          <mu2>1</mu2>
        </ode>
      </friction>
    </surface>
    <inertial>
      <origin rpy="0 0 0" xyz="0 0 0"/>
      <mass value="4319.562500000001"/>
      <inertia ixx="81.89170572916669" ixy="0" ixz="0" iyy="81.89170572916669" iyz="0" izz="134.98632812500003"/>
    </inertial>
  </link>
  <link name="right_skid_wheel_free">
    <visual>
      <origin rpy="0 0 0" xyz="0 0 0"/>
      <geometry>
        <cylinder length="0.2" radius="0.25"/>
      </geometry>
      <material name="wheel_material">
        <color rgba="0.5 0.5 0.5 1.0"/>
      </material>
    </visual>
    <collision>
      <origin rpy="0 0 0" xyz="0 0 0"/>
      <geometry>
        <cylinder length="0.2" radius="0.25"/>
      </geometry>
    </collision>
    <surface>
      <friction>
        <ode>
          <mu>1</mu>
          <mu2>1</mu2>
        </ode>
      </friction>
    </surface>
    <inertial>
      <origin rpy="0 0 0" xyz="0 0 0"/>
      <mass value="4319.562500000001"/>
      <inertia ixx="81.89170572916669" ixy="0" ixz="0" iyy="81.89170572916669" iyz="0" izz="134.98632812500003"/>
    </inertial>
  </link>
  <ros2_control name="GazeboSystem" type="system">
    <!-- <hardware>
                <plugin>gazebo_ros2_control/GazeboSystem</plugin>
            </hardware> -->
    <hardware>
      <plugin>gz_ros2_control/GazeboSimSystem</plugin>
    </hardware>
    <joint name="plow_to_base">
      <command_interface name="velocity">
        <param name="min">-1.0</param>
        <param name="max">1.0</param>
      </command_interface>
      <state_interface name="position"/>
      <state_interface name="velocity"/>
      <!-- <state_interface name="effort"/> -->
    </joint>
    <joint name="excavator_slew">
      <command_interface name="velocity">
        <param name="min">-1.0</param>
        <param name="max">1.0</param>
      </command_interface>
      <state_interface name="position"/>
      <state_interface name="velocity"/>
      <!-- <state_interface name="effort"/> -->
    </joint>
    <joint name="cabin_to_swing">
      <command_interface name="velocity">
        <param name="min">-1.0</param>
        <param name="max">1.0</param>
      </command_interface>
      <state_interface name="position"/>
      <state_interface name="velocity"/>
      <!-- <state_interface name="effort"/> -->
    </joint>
    <joint name="swing_to_boom">
      <command_interface name="velocity">
        <param name="min">-1.0</param>
        <param name="max">1.0</param>
      </command_interface>
      <state_interface name="position"/>
      <state_interface name="velocity"/>
      <!-- <state_interface name="effort"/> -->
    </joint>
    <joint name="boom_to_arm">
      <command_interface name="velocity">
        <param name="min">-1.0</param>
        <param name="max">1.0</param>
      </command_interface>
      <state_interface name="position"/>
      <state_interface name="velocity"/>
      <!-- <state_interface name="effort"/> -->
    </joint>
    <joint name="arm_to_bucket">
      <command_interface name="velocity">
        <param name="min">-1.0</param>
        <param name="max">1.0</param>
      </command_interface>
      <state_interface name="position"/>
      <state_interface name="velocity"/>
      <!-- <state_interface name="effort"/> -->
    </joint>
  </ros2_control>
  <gazebo>
    <!-- <plugin name="gazebo_ros2_control" filename="libgazebo_ros2_control.so"> -->
    <plugin filename="gz_ros2_control-system" name="gz_ros2_control::GazeboSimROS2ControlPlugin">
      <parameters>/home/moog-2/nav2_ws/install/earth_gz_ign/share/earth_gz_ign/params/vc.yaml</parameters>
      <controller_manager_name>controller_manager</controller_manager_name>
    </plugin>
  </gazebo>
  <!-- <gazebo>
            <plugin name="two_wheeled_robot_diff_drive" filename="libgazebo_ros_diff_drive.so">
                <num_wheel_pairs>2</num_wheel_pairs>

                <left_joint>${left_spinning_to_turret_joint_name}</left_joint>
                <left_joint>${left_front_to_turret_joint_name}</left_joint>
                <right_joint>${right_spinning_to_turret_joint_name}</right_joint>
                <right_joint>${right_front_to_turret_joint_name}</right_joint>

                <wheel_separation>1.75</wheel_separation>
                <wheel_separation>1.75</wheel_separation>

                <wheel_diameter>${wheel_radius*2}</wheel_diameter>
                <wheel_diameter>${wheel_radius*2}</wheel_diameter>

                <max_wheel_torque>10000</max_wheel_torque>
                <max_wheel_acceleration>1.0</max_wheel_acceleration>

                <publish_odom>true</publish_odom>
                <publish_odom_tf>true</publish_odom_tf>
                <publish_wheel_tf>true</publish_wheel_tf>

                <odometry_frame>odom</odometry_frame>
                <robot_base_frame>base_link</robot_base_frame>
            </plugin>
        </gazebo> -->
</robot>
